Workbook

Sheet Seguridad Social
A1: salario minimo
A2: EMPLEADO | B2: CEDULA | C2: NOMBRES | D2: TIPO DE SALARI | E2: DIAS LABORADOS MES | F2: DIAS VAC/LICENCIAS | G2: DIAS INCAPACIDAD | H2: INGRESOS SALARIALES | I2: IBC INICIAL | J2: INGRESOS NO SALARIALES | K2: TOTAL INGRESOS | L2: 40% INGRESOS | M2: EXCESO | N2: 0.7 | O2: IBC 1393 | P2: IBC MES ANTERIOR | Q2: IBC VACACIONES | R2: IBC INCAPACIDADES/LICENCIAS | S2: TOTAL IBC MES SEGURIDAD SOCIAL | T2: PENSIONADO | U2: APORTE SALUD | V2: APORTE SALUD SISTEMA | W2: DIFERENCIA | X2: APORTE PENSION | Y2: APORTE PENSION SISTEMA | Z2: DIFERENCIA | AA2: TOTAL IBC MES FONDO | AB2: APORTE FONDO | AC2: APORTE FONDO SISTEMA | AD2: DIFERENCIA | AF2: nuevo salario | AG2: IBC ACTUAL | AH2: IBC MES ANTERIOR | AJ2: fs empleador | AK2: OBSERVACIONES
A3: 20031311 | B3: 46377202 | C3: RODRIGUEZ CRUZ EDITH JULIETA | D3: Integral | E3: 31 | F3: 1 | G3: 0 | H3: 30725865 | I3: 21508106 | J3: 921700 | K3: 31647565 | L3: 12659026 | P3: 18468313 | Q3: 615610 | R3: 0 | V3: 884948 | Y3: 884948 | AC3: 221400 | AF3: =VLOOKUP(A3,Devengos!$A$4:$I$389,9,0) -> 22761766 | AG3: =IF(D3="Integral",ROUND(AF3*70%,0),AF3) -> 15933236 | AH3: =IFERROR(VLOOKUP(B3,'Planilla Mes anterior'!$CX:$CY,2,0),0) -> 18468313 | AJ3: 0
A4: 20032632 | B4: 1.0208468e+09 | C4: AVELLO ALVAREZ JUAN JOSE | D4: Integral | E4: 30 | F4: 0 | G4: 0 | H4: 22761765 | I4: 15933235 | J4: 859700 | K4: 23621465 | L4: 9448586 | P4: 15933236 | Q4: 0 | R4: 0 | V4: 637329 | Y4: 637329 | AC4: 159400 | AF4: =VLOOKUP(A4,Devengos!$A$4:$I$389,9,0) -> 22761765 | AG4: =IF(D4="Integral",ROUND(AF4*70%,0),AF4) -> 15933236 | AH4: =IFERROR(VLOOKUP(B4,'Planilla Mes anterior'!$CX:$CY,2,0),0) -> 15933236 | AJ4: 0
A5: 20032638 | B5: 94416294 | C5: VALDERRAMA CONCHA ANDRES FELIPE | D5: Integral | E5: 31 | F5: 0 | G5: 0 | H5: 42589681 | I5: 29812777 | J5: 2288938 | K5: 44878619 | L5: 17951448 | P5: 28800088 | Q5: 0 | R5: 0 | V5: 1192511 | Y5: 1192511 | AC5: 417500 | AF5: =VLOOKUP(A5,Devengos!$A$4:$I$389,9,0) -> 33602815 | AG5: =IF(D5="Integral",ROUND(AF5*70%,0),AF5) -> 23521971 | AH5: =IFERROR(VLOOKUP(B5,'Planilla Mes anterior'!$CX:$CY,2,0),0) -> 28800088 | AJ5: 0
A6: 20032640 | B6: 51813374 | C6: SANCHEZ TEJADA ADRIANA | D6: Integral | E6: 31 | F6: 0 | G6: 0 | H6: 33430177 | I6: 23401124 | J6: 1065836 | K6: 34496013 | L6: 13798405 | P6: 19218024 | Q6: 0 | R6: 0 | V6: 936045 | Y6: 0 | AB6: 0 | AC6: 0 | AD6: 0 | AF6: =VLOOKUP(A6,Devengos!$A$4:$I$389,9,0) -> 22819376 | AG6: =IF(D6="Integral",ROUND(AF6*70%,0),AF6) -> 15973563 | AH6: =IFERROR(VLOOKUP(B6,'Planilla Mes anterior'!$CX:$CY,2,0),0) -> 19218024 | AJ6: 0
A7: 20032652 | B7: 98624466 | C7: GARCIA LEON EDISSON AUGUSTO | D7: Normal | E7: 30 | F7: 0 | G7: 2 | H7: 11096741 | I7: 11096741 | J7: 811300 | K7: 11908041 | L7: 4763216 | P7: 11096741 | Q7: 0 | R7: 0 | T7: 0 | V7: 443869 | Y7: 443869 | AC7: 111000 | AF7: =VLOOKUP(A7,Devengos!$A$4:$I$389,9,0) -> 11096741 | AG7: =IF(D7="Integral",ROUND(AF7*70%,0),AF7) -> 11096741 | AH7: =IFERROR(VLOOKUP(B7,'Planilla Mes anterior'!$CX:$CY,2,0),0) -> 11096741 | AJ7: 0
A8: 20039921 | B8: 79864894 | C8: MOLINA JUNCO HUGO ALEXANDER | D8: Normal | E8: 30 | F8: 0 | G8: 0 | H8: 12941846 | I8: 12941846 | J8: 829900 | K8: 13771746 | L8: 5508698 | P8: 12941846 | Q8: 0 | R8: 0 | T8: 0 | V8: 517674 | Y8: 517674 | AC8: 129600 | AF8: =VLOOKUP(A8,Devengos!$A$4:$I$389,9,0) -> 12941846 | AG8: =IF(D8="Integral",ROUND(AF8*70%,0),AF8) -> 12941846 | AH8: =IFERROR(VLOOKUP(B8,'Planilla Mes anterior'!$CX:$CY,2,0),0) -> 12941846 | AJ8: 0
A9: 20042066 | B9: 94469034 | C9: BRAVO SOLARTE HECTOR MARIO | D9: Integral | E9: 42 | F9: 0 | G9: 11 | H9: 32559810 | I9: 22791867 | J9: 931900 | K9: 33491710 | L9: 13396684 | P9: 24539605 | Q9: 0 | R9: 0 | S9: 23129377 | U9: 925175.06 | V9: 925175 | W9: 0.064 | Y9: 925175 | AC9: 231600 | AF9: =VLOOKUP(A9,Devengos!$A$4:$I$389,9,0) -> 30673334 | AG9: =IF(D9="Integral",ROUND(AF9*70%,0),AF9) -> 21471334 | AH9: =IFERROR(VLOOKUP(B9,'Planilla Mes anterior'!$CX:$CY,2,0),0) -> 24539605 | AJ9: 0 | AK9: TOMA SALARIO * 70%+ LOS SALARIALES AL 70% Y EL PAGO DEL 100% DE LA INCAPACIDAD INCLUIDO EL AUXILIO ASUMIDO
A10: 20047370 | B10: 1127577184 | C10: MEZA PAUL MARIA ALEJANDRA | D10: Integral | E10: 31 | F10: 0 | G10: 0 | H10: 29773237 | I10: 20841266 | J10: 1108900 | K10: 30882137 | L10: 12352855 | P10: 18666001 | Q10: 0 | R10: 0 | V10: 833651 | Y10: 833651 | AC10: 208600 | AF10: =VLOOKUP(A10,Devengos!$A$4:$I$389,9,0) -> 23832382 | AG10: =IF(D10="Integral",ROUND(AF10*70%,0),AF10) -> 16682667 | AH10: =IFERROR(VLOOKUP(B10,'Planilla Mes anterior'!$CX:$CY,2,0),0) -> 18666001 | AJ10: 0
A11: 20049357 | B11: 424785 | C11: SEGURA FRANCOIS ALBERT | D11: Integral | E11: 31 | F11: 0 | G11: 0 | H11: 27738862 | I11: 19417203 | J11: 894500 | K11: 28633362 | L11: 11453345 | P11: 17675220 | Q11: 0 | R11: 0 | V11: 776688 | Y11: 776688 | AC11: 194200 | AF11: =VLOOKUP(A11,Devengos!$A$4:$I$389,9,0) -> 22761766 | AG11: =IF(D11="Integral",ROUND(AF11*70%,0),AF11) -> 15933236 | AH11: =IFERROR(VLOOKUP(B11,'Planilla Mes anterior'!$CX:$CY,2,0),0) -> 17675220 | AJ11: 0
A12: 20059280 | B12: 71269226 | C12: RUIZ MARTINEZ JUAN CAMILO | D12: Integral | E12: 30 | F12: 1 | G12: 0 | H12: 24203344 | I12: 16942341 | J12: 875300 | K12: 25078644 | L12: 10031458 | P12: 15933236 | Q12: 531108 | R12: 0 | V12: 698938 | Y12: 698938 | AC12: 175000 | AF12: =VLOOKUP(A12,Devengos!$A$4:$I$389,9,0) -> 25037942 | AG12: =IF(D12="Integral",ROUND(AF12*70%,0),AF12) -> 17526559 | AH12: =IFERROR(VLOOKUP(B12,'Planilla Mes anterior'!$CX:$CY,2,0),0) -> 15933236 | AJ12: 0
A13: 20060771 | B13: 1.0184065e+09 | C13: RICO HERNANDEZ OSCAR EDUARDO | D13: Normal | E13: 30 | F13: 2 | G13: 0 | H13: 13952910 | I13: 13952910 | J13: 869100 | K13: 14822010 | L13: 5928804 | P13: 43772625 | Q13: 2918175 | R13: 0 | T13: 0 | V13: 674843 | Y13: 674843 | AC13: 168800 | AF13: =VLOOKUP(A13,Devengos!$A$4:$I$389,9,0) -> 14949546 | AG13: =IF(D13="Integral",ROUND(AF13*70%,0),AF13) -> 14949546 | AH13: =IFERROR(VLOOKUP(B13,'Planilla Mes anterior'!$CX:$CY,2,0),0) -> 43772625 | AJ13: 0
A14: 20060845 | B14: 1018406436 | C14: RODRIGUEZ MOLINA JOSE DAVID | D14: Integral | E14: 30 | F14: 0 | G14: 0 | H14: 22761765 | I14: 15933235 | J14: 859700 | K14: 23621465 | L14: 9448586 | P14: 15955734 | Q14: 0 | R14: 0 | V14: 637329 | Y14: 637329 | AC14: 159400 | AF14: =VLOOKUP(A14,Devengos!$A$4:$I$389,9,0) -> 22761765 | AG14: =IF(D14="Integral",ROUND(AF14*70%,0),AF14) -> 15933236 | AH14: =IFERROR(VLOOKUP(B14,'Planilla Mes anterior'!$CX:$CY,2,0),0) -> 15955734 | AJ14: 0
A15: 20065526 | B15: 52530451 | C15: PEÑA CARDENAS ERIKA YOLIMA | D15: Normal | E15: 30 | F15: 0 | G15: 0 | H15: 9525854 | I15: 9525854 | J15: 795700 | K15: 10321554 | L15: 4128622 | P15: 9525854 | Q15: 0 | R15: 0 | T15: 0 | V15: 381034 | Y15: 381034 | AC15: 95400 | AF15: =VLOOKUP(A15,Devengos!$A$4:$I$389,9,0) -> 9525854 | AG15: =IF(D15="Integral",ROUND(AF15*70%,0),AF15) -> 9525854 | AH15: =IFERROR(VLOOKUP(B15,'Planilla Mes anterior'!$CX:$CY,2,0),0) -> 9525854 | AJ15: 0
A16: 20066234 | B16: 502210 | C16: TACORONTE RIVERO ERNESTO LUIS | D16: Integral | E16: 30 | F16: 0 | G16: 0 | H16: 28483101 | I16: 19938171 | J16: 899700 | K16: 29382801 | L16: 11753120 | P16: 19938171 | Q16: 0 | R16: 0 | V16: 797527 | Y16: 797527 | AC16: 199400 | AF16: =VLOOKUP(A16,Devengos!$A$4:$I$389,9,0) -> 28483101 | AG16: =IF(D16="Integral",ROUND(AF16*70%,0),AF16) -> 19938171 | AH16: =IFERROR(VLOOKUP(B16,'Planilla Mes anterior'!$CX:$CY,2,0),0) -> 19938171 | AJ16: 0
A17: 20066799 | B17: 1020796094 | C17: ALBESANO RODRIGUEZ TOMAS ENRICO | D17: Normal | E17: 31 | F17: 0 | G17: 0 | H17: 12834012 | I17: 12834012 | J17: 2525372 | K17: 15359384 | L17: 6143754 | P17: 13976000 | Q17: 0 | R17: 0 | T17: 0 | V17: 513360 | Y17: 513360 | AC17: 128400 | AF17: =VLOOKUP(A17,Devengos!$A$4:$I$389,9,0) -> 12525864 | AG17: =IF(D17="Integral",ROUND(AF17*70%,0),AF17) -> 12525864 | AH17: =IFERROR(VLOOKUP(B17,'Planilla Mes anterior'!$CX:$CY,2,0),0) -> 13976000 | AJ17: 0
A18: 20066836 | B18: 72266298 | C18: ZARATE LOPEZ MARCO TULIO | D18: Normal | E18: 31 | F18: 1 | G18: 0 | H18: 27218173 | I18: 27218173 | J18: 1243949 | K18: 28462122 | L18: 11384849 | P18: 24946729 | Q18: 831558 | R18: 0 | T18: 0 | V18: 1121989 | Y18: 1121989 | AC18: 336800 | AF18: =VLOOKUP(A18,Devengos!$A$4:$I$389,9,0) -> 22761765 | AG18: =IF(D18="Integral",ROUND(AF18*70%,0),AF18) -> 22761765 | AH18: =IFERROR(VLOOKUP(B18,'Planilla Mes anterior'!$CX:$CY,2,0),0) -> 24946729 | AJ18: 0
A19: 20068049 | B19: 1014191248 | C19: CALDERON MANCHEGO JOSE ERNESTO | D19: Normal | E19: 30 | F19: 0 | G19: 0 | H19: 8956566 | I19: 8956566 | J19: 789900 | K19: 9746466 | L19: 3898586 | P19: 8956566 | Q19: 0 | R19: 0 | T19: 0 | V19: 358263 | Y19: 358263 | AC19: 89600 | AF19: =VLOOKUP(A19,Devengos!$A$4:$I$389,9,0) -> 8956566 | AG19: =IF(D19="Integral",ROUND(AF19*70%,0),AF19) -> 8956566 | AH19: =IFERROR(VLOOKUP(B19,'Planilla Mes anterior'!$CX:$CY,2,0),0) -> 8956566 | AJ19: 0
A20: 20068059 | B20: 79521449 | C20: RAMIREZ RODRIGUEZ JUVENAL HUMBERTO | D20: Normal | E20: 30 | F20: 0 | G20: 0 | H20: 13325016 | I20: 13325016 | J20: 1637817 | K20: 14962833 | L20: 5985133 | P20: 14162837 | Q20: 0 | R20: 0 | T20: 0 | V20: 533001 | Y20: 533001 | AC20: 133400 | AF20: =VLOOKUP(A20,Devengos!$A$4:$I$389,9,0) -> 13325016 | AG20: =IF(D20="Integral",ROUND(AF20*70%,0),AF20) -> 13325016 | AH20: =IFERROR(VLOOKUP(B20,'Planilla Mes anterior'!$CX:$CY,2,0),0) -> 14162837 | AJ20: 0
A21: 20069425 | B21: 88233100 | C21: LIZCANO GOMEZ RICARDO | D21: Integral | E21: 30 | F21: 0 | G21: 0 | H21: 22761765 | I21: 15933235 | J21: 859700 | K21: 23621465 | L21: 9448586 | P21: 15933236 | Q21: 0 | R21: 0 | V21: 637329 | Y21: 637329 | AC21: 159400 | AF21: =VLOOKUP(A21,Devengos!$A$4:$I$389,9,0) -> 22761765 | AG21: =IF(D21="Integral",ROUND(AF21*70%,0),AF21) -> 15933236 | AH21: =IFERROR(VLOOKUP(B21,'Planilla Mes anterior'!$CX:$CY,2,0),0) -> 15933236 | AJ21: 0
A22: 20073842 | B22: 16928777 | C22: GOMEZ SANTOFIMIO NESTOR JAVIER | D22: Integral | E22: 30 | F22: 0 | G22: 0 | H22: 27360609 | I22: 19152426 | J22: 891900 | K22: 28252509 | L22: 11301004 | P22: 19152427 | Q22: 0 | R22: 0 | V22: 766097 | Y22: 766097 | AC22: 191600 | AF22: =VLOOKUP(A22,Devengos!$A$4:$I$389,9,0) -> 27360609 | AG22: =IF(D22="Integral",ROUND(AF22*70%,0),AF22) -> 19152426 | AH22: =IFERROR(VLOOKUP(B22,'Planilla Mes anterior'!$CX:$CY,2,0),0) -> 19152427 | AJ22: 0
A23: 20075245 | B23: 1144151741 | C23: RESTREPO MARIN PAOLA | D23: Normal | E23: 30 | F23: 0 | G23: 0 | H23: 7411661 | I23: 7411661 | J23: 975529 | K23: 8387190 | L23: 3354876 | P23: 7411661 | Q23: 0 | R23: 0 | T23: 0 | V23: 296466 | Y23: 296466 | AC23: 74200 | AF23: =VLOOKUP(A23,Devengos!$A$4:$I$389,9,0) -> 7411661 | AG23: =IF(D23="Integral",ROUND(AF23*70%,0),AF23) -> 7411661 | AH23: =IFERROR(VLOOKUP(B23,'Planilla Mes anterior'!$CX:$CY,2,0),0) -> 7411661 | AJ23: 0
A24: 20075298 | B24: 1032380630 | C24: POLO TORRES SORAIMA SELENE | D24: Normal | E24: 30 | F24: 10 | G24: 0 | H24: 8311974 | I24: 8311974 | J24: 825100 | K24: 9137074 | L24: 3654830 | P24: 12467961 | Q24: 4155987 | R24: 0 | T24: 0 | V24: 498719 | Y24: 498719 | AC24: 124800 | AF24: =VLOOKUP(A24,Devengos!$A$4:$I$389,9,0) -> 12467961 | AG24: =IF(D24="Integral",ROUND(AF24*70%,0),AF24) -> 12467961 | AH24: =IFERROR(VLOOKUP(B24,'Planilla Mes anterior'!$CX:$CY,2,0),0) -> 12467961 | AJ24: 0
A25: 20075317 | B25: 94552091 | C25: VELASCO BURBANO GUSTAVO ADOLFO | D25: Normal | E25: 30 | F25: 0 | G25: 0 | H25: 8920122 | I25: 8920122 | J25: 789700 | K25: 9709822 | L25: 3883929 | P25: 9411060 | Q25: 0 | R25: 0 | T25: 0 | V25: 356805 | Y25: 356805 | AC25: 89400 | AF25: =VLOOKUP(A25,Devengos!$A$4:$I$389,9,0) -> 8324189 | AG25: =IF(D25="Integral",ROUND(AF25*70%,0),AF25) -> 8324189 | AH25: =IFERROR(VLOOKUP(B25,'Planilla Mes anterior'!$CX:$CY,2,0),0) -> 9411060 | AJ25: 0
A26: 20077129 | B26: 38565334 | C26: CALDERON QUEVEDO EVELIN ELISA | D26: Integral | E26: 31 | F26: 0 | G26: 0 | H26: 29343117 | I26: 20540182 | J26: 905900 | K26: 30249017 | L26: 12099607 | P26: 15933237 | Q26: 0 | R26: 0 | V26: 821607 | Y26: 821607 | AC26: 205600 | AF26: =VLOOKUP(A26,Devengos!$A$4:$I$389,9,0) -> 22761766 | AG26: =IF(D26="Integral",ROUND(AF26*70%,0),AF26) -> 15933236 | AH26: =IFERROR(VLOOKUP(B26,'Planilla Mes anterior'!$CX:$CY,2,0),0) -> 15933237 | AJ26: 0
A27: 20080480 | B27: 1.0207461e+09 | C27: MITROSBARAS VARGAS COSTANTINO | D27: Integral | E27: 31 | F27: 0 | G27: 0 | H27: 28470583 | I27: 19929408 | J27: 899700 | K27: 29370283 | L27: 11748113 | P27: 20889137 | Q27: 0 | R27: 0 | V27: 797176 | Y27: 797176 | AC27: 199400 | AF27: =VLOOKUP(A27,Devengos!$A$4:$I$389,9,0) -> 22761766 | AG27: =IF(D27="Integral",ROUND(AF27*70%,0),AF27) -> 15933236 | AH27: =IFERROR(VLOOKUP(B27,'Planilla Mes anterior'!$CX:$CY,2,0),0) -> 20889137 | AJ27: 0
A28: 20081518 | B28: 7183581 | C28: BLANCO LEGUIZAMON DIEGO RICARDO | D28: Integral | E28: 30 | F28: 0 | G28: 0 | H28: 22761766 | I28: 15933236 | J28: 1362295 | K28: 24124061 | L28: 9649624 | P28: 27123777 | Q28: 0 | R28: 0 | V28: 637329 | Y28: 637329 | AC28: 159400 | AF28: =VLOOKUP(A28,Devengos!$A$4:$I$389,9,0) -> 22761766 | AG28: =IF(D28="Integral",ROUND(AF28*70%,0),AF28) -> 15933236 | AH28: =IFERROR(VLOOKUP(B28,'Planilla Mes anterior'!$CX:$CY,2,0),0) -> 18986644 | AJ28: 0 | AK28: TOMA SALARIO * 70%+ LOS SALARIALES AL 70% Y EL PAGO DEL 100% DE LA INCAPACIDAD INCLUIDO EL AUXILIO ASUMIDO
A29: 20087553 | B29: 11233975 | C29: BELTRAN RODRIGUEZ EDICSON ARNETH | D29: Normal | E29: 30 | F29: 0 | G29: 0 | H29: 5628456 | I29: 5628456 | J29: 700300 | K29: 6328756 | L29: 2531502 | P29: 5628456 | Q29: 0 | R29: 0 | T29: 0 | V29: 225138 | Y29: 225138 | AC29: 0 | AF29: =VLOOKUP(A29,Devengos!$A$4:$I$389,9,0) -> 5628456 | AG29: =IF(D29="Integral",ROUND(AF29*70%,0),AF29) -> 5628456 | AH29: =IFERROR(VLOOKUP(B29,'Planilla Mes anterior'!$CX:$CY,2,0),0) -> 5628456 | AJ29: 0
A30: 20087555 | B30: 13928419 | C30: JAUREGUI PACHECO DUBIAN YAMID | D30: Normal | E30: 30 | F30: 0 | G30: 2 | H30: 8818009 | I30: 8818009 | J30: 788500 | K30: 9606509 | L30: 3842604 | P30: 8818010 | Q30: 0 | R30: 0 | T30: 0 | V30: 352720 | Y30: 352720 | AC30: 88200 | AF30: =VLOOKUP(A30,Devengos!$A$4:$I$389,9,0) -> 8818010 | AG30: =IF(D30="Integral",ROUND(AF30*70%,0),AF30) -> 8818010 | AH30: =IFERROR(VLOOKUP(B30,'Planilla Mes anterior'!$CX:$CY,2,0),0) -> 8818010 | AJ30: 0
A31: 20088951 | B31: 743339 | C31: AULAR CASTELLANOS LISETTE KATHERINE | D31: Normal | E31: 30 | F31: 0 | G31: 0 | H31: 9703467 | I31: 9703467 | J31: 797500 | K31: 10500967 | L31: 4200387 | P31: 9703467 | Q31: 0 | R31: 0 | T31: 0 | V31: 388139 | Y31: 388139 | AC31: 97200 | AF31: =VLOOKUP(A31,Devengos!$A$4:$I$389,9,0) -> 9703467 | AG31: =IF(D31="Integral",ROUND(AF31*70%,0),AF31) -> 9703467 | AH31: =IFERROR(VLOOKUP(B31,'Planilla Mes anterior'!$CX:$CY,2,0),0) -> 9703467 | AJ31: 0
A32: 20090398 | B32: 1143831936 | C32: ZURITA RAMOS JEISON ANDRES | D32: Normal | E32: 30 | F32: 0 | G32: 0 | H32: 7378396 | I32: 7378396 | J32: 774100 | K32: 8152496 | L32: 3260998 | P32: 7378396 | Q32: 0 | R32: 0 | T32: 0 | V32: 295136 | Y32: 295136 | AC32: 73800 | AF32: =VLOOKUP(A32,Devengos!$A$4:$I$389,9,0) -> 7378396 | AG32: =IF(D32="Integral",ROUND(AF32*70%,0),AF32) -> 7378396 | AH32: =IFERROR(VLOOKUP(B32,'Planilla Mes anterior'!$CX:$CY,2,0),0) -> 7378396 | AJ32: 0
A33: 20090881 | B33: 79957003 | C33: MORENO TORRES JUAN PABLO | D33: Normal | E33: 30 | F33: 0 | G33: 0 | H33: 9870390 | I33: 9870390 | J33: 1468736 | K33: 11339126 | L33: 4535650 | P33: 9870390 | Q33: 0 | R33: 0 | T33: 0 | V33: 394816 | Y33: 394816 | AC33: 98800 | AF33: =VLOOKUP(A33,Devengos!$A$4:$I$389,9,0) -> 9870390 | AG33: =IF(D33="Integral",ROUND(AF33*70%,0),AF33) -> 9870390 | AH33: =IFERROR(VLOOKUP(B33,'Planilla Mes anterior'!$CX:$CY,2,0),0) -> 9870390 | AJ33: 0
A34: 20091394 | B34: 1.0537795e+09 | C34: EPALZA GONZALEZ JHON ALEJANDRO | D34: Integral | E34: 31 | F34: 10 | G34: 0 | H34: 19800886 | I34: 13860620 | J34: 897900 | K34: 20698786 | L34: 8279514 | P34: 17552468 | Q34: 5850823 | R34: 0 | V34: 788457 | Y34: 788457 | AC34: 197600 | AF34: =VLOOKUP(A34,Devengos!$A$4:$I$389,9,0) -> 22761766 | AG34: =IF(D34="Integral",ROUND(AF34*70%,0),AF34) -> 15933236 | AH34: =IFERROR(VLOOKUP(B34,'Planilla Mes anterior'!$CX:$CY,2,0),0) -> 17552468 | AJ34: 0
A35: 20092674 | B35: 52910485 | C35: RINCON GARZON DIANA YOMARA | D35: Normal | E35: 30 | F35: 0 | G35: 0 | H35: 6864198 | I35: 6864198 | J35: 700300 | K35: 7564498 | L35: 3025799 | P35: 6864198 | Q35: 0 | R35: 0 | T35: 0 | V35: 274568 | Y35: 274568 | AC35: 0 | AF35: =VLOOKUP(A35,Devengos!$A$4:$I$389,9,0) -> 6864198 | AG35: =IF(D35="Integral",ROUND(AF35*70%,0),AF35) -> 6864198 | AH35: =IFERROR(VLOOKUP(B35,'Planilla Mes anterior'!$CX:$CY,2,0),0) -> 6864198 | AJ35: 0
A36: 20095697 | B36: 52704384 | C36: CAVIEDES LUNA GYSELLA | D36: Normal | E36: 31 | F36: 0 | G36: 0 | H36: 4707860 | I36: 4707860 | J36: 760609 | K36: 5468469 | L36: 2187388 | P36: 3713188 | Q36: 0 | R36: 0 | T36: 0 | V36: 188314 | Y36: 188314 | AC36: 0 | AF36: =VLOOKUP(A36,Devengos!$A$4:$I$389,9,0) -> 3713187.9 | AG36: =IF(D36="Integral",ROUND(AF36*70%,0),AF36) -> 3713187.9 | AH36: =IFERROR(VLOOKUP(B36,'Planilla Mes anterior'!$CX:$CY,2,0),0) -> 3713188 | AJ36: 0
A37: 20096418 | B37: 80093596 | C37: CANTOR CORTES HECTOR MAURICIO | D37: Integral | E37: 30 | F37: 1 | G37: 0 | H37: 26798161 | I37: 18758713 | J37: 1439924 | K37: 28238085 | L37: 11295234 | P37: 19405565 | Q37: 646852 | R37: 0 | V37: 776223 | Y37: 776223 | AC37: 194200 | AF37: =VLOOKUP(A37,Devengos!$A$4:$I$389,9,0) -> 27722235 | AG37: =IF(D37="Integral",ROUND(AF37*70%,0),AF37) -> 19405565 | AH37: =IFERROR(VLOOKUP(B37,'Planilla Mes anterior'!$CX:$CY,2,0),0) -> 19405565 | AJ37: 0
A38: 20097480 | B38: 29659821 | C38: BENAVIDES URIBE ISABEL CRISTINA | D38: Normal | E38: 31 | F38: 0 | G38: 0 | H38: 13337351 | I38: 13337351 | J38: 833700 | K38: 14171051 | L38: 5668420 | P38: 16092832 | Q38: 0 | R38: 0 | T38: 0 | V38: 533494 | Y38: 533494 | AC38: 133400 | AF38: =VLOOKUP(A38,Devengos!$A$4:$I$389,9,0) -> 12245239 | AG38: =IF(D38="Integral",ROUND(AF38*70%,0),AF38) -> 12245239 | AH38: =IFERROR(VLOOKUP(B38,'Planilla Mes anterior'!$CX:$CY,2,0),0) -> 16092832 | AJ38: 0
A39: 20097763 | B39: 80124057 | C39: ARAQUE GUERRERO JAIME ALEJANDRO | D39: Normal | E39: 31 | F39: 0 | G39: 0 | H39: 15632953 | I39: 15632953 | J39: 856700 | K39: 16489653 | L39: 6595861 | P39: 14884659 | Q39: 0 | R39: 0 | T39: 0 | V39: 625318 | Y39: 625318 | AC39: 156400 | AF39: =VLOOKUP(A39,Devengos!$A$4:$I$389,9,0) -> 12639772 | AG39: =IF(D39="Integral",ROUND(AF39*70%,0),AF39) -> 12639772 | AH39: =IFERROR(VLOOKUP(B39,'Planilla Mes anterior'!$CX:$CY,2,0),0) -> 14884659 | AJ39: 0
A40: 20098732 | B40: 53010880 | C40: BULLA LOPEZ CLAUDIA MARCELA | D40: Normal | E40: 30 | F40: 0 | G40: 0 | H40: 9483131 | I40: 9483131 | J40: 795300 | K40: 10278431 | L40: 4111372 | P40: 9595056 | Q40: 0 | R40: 0 | T40: 0 | V40: 379325 | Y40: 379325 | AC40: 95000 | AF40: =VLOOKUP(A40,Devengos!$A$4:$I$389,9,0) -> 9483131 | AG40: =IF(D40="Integral",ROUND(AF40*70%,0),AF40) -> 9483131 | AH40: =IFERROR(VLOOKUP(B40,'Planilla Mes anterior'!$CX:$CY,2,0),0) -> 9595056 | AJ40: 0
...
